[07/mar/2019 15:00:31] ERROR [django.request:256] Internal Server Error: /ingresos/cpb_rec_cobranza/nuevo_cobro/
Traceback (most recent call last):
  File "C:\Python27\lib\site-packages\django\core\handlers\base.py", line 132, in get_response
    response = wrapped_callback(request, *callback_args, **callback_kwargs)
  File "C:\Python27\lib\site-packages\django\views\generic\base.py", line 71, in view
    return self.dispatch(request, *args, **kwargs)
  File "C:\Python27\lib\site-packages\django\utils\decorators.py", line 34, in _wrapper
    return bound_func(*args, **kwargs)
  File "C:\Python27\lib\site-packages\django\contrib\auth\decorators.py", line 22, in _wrapped_view
    return view_func(request, *args, **kwargs)
  File "C:\Python27\lib\site-packages\django\utils\decorators.py", line 30, in bound_func
    return func.__get__(self, type(self))(*args2, **kwargs2)
  File "D:\Repo\ironweb\ingresos\views.py", line 1628, in dispatch
    return super(CPBCobrarCreateView, self).dispatch(*args, **kwargs)
  File "C:\Python27\lib\site-packages\django\views\generic\base.py", line 89, in dispatch
    return handler(request, *args, **kwargs)
  File "D:\Repo\ironweb\ingresos\views.py", line 1644, in get
    form = self.get_form(form_class)
  File "C:\Python27\lib\site-packages\django\views\generic\edit.py", line 74, in get_form
    return form_class(**self.get_form_kwargs())
  File "D:\Repo\ironweb\ingresos\forms.py", line 536, in __init__
    self.fields['pto_vta'].initial = get_pv_defecto(request)
  File "D:\Repo\ironweb\general\forms.py", line 63, in get_pv_defecto
    num_pv=empresa_actual(request).pto_vta_defecto.numero
  File "C:\Python27\lib\site-packages\django\db\models\fields\related.py", line 604, in __get__
    rel_obj = qs.get()
  File "C:\Python27\lib\site-packages\django\db\models\query.py", line 334, in get
    self.model._meta.object_name
DoesNotExist: cpb_pto_vta matching query does not exist.
